<mujoco>
  <option gravity="0 0 -9.81" />
  <compiler angle="radian" />
  <visual>
    <headlight diffuse="0.6 0.6 0.6" ambient="0.1 0.1 0.1" specular="0.9 0.9 0.9"/>
    <rgba haze="0.15 0.25 0.35 1"/>
    <global azimuth="140" elevation="-20"/>
  </visual>
  <asset>
    <texture type="skybox" builtin="gradient" rgb1="0.3 0.5 0.7" rgb2="0 0 0" width="512" height="3072"/>
    <texture type="2d" name="groundplane" builtin="checker" mark="edge" rgb1="0.2 0.3 0.4" rgb2="0.1 0.2 0.3"
      markrgb="0.8 0.8 0.8" width="300" height="300"/>
    <material name="groundplane" texture="groundplane" texuniform="true" texrepeat="5 5" reflectance="0.2"/>
  </asset>
  <worldbody>
    <geom name="floor" pos="0 0 -0.5" size="0 0 0.05" type="plane" material="groundplane"/>
    <body name="cylinder_body" pos="0.1381 0.09 0.2344">
      <joint name="joint0" type="hinge" axis="0 -1 0" pos="0 0 0.5" damping="2" frictionloss="2"/>
      <geom type="cylinder" size="0.06 0.2344" rgba="1 0.75 0.8 1"/>
      <inertial pos="0 0 0" mass="4.57" diaginertia="0.1 0.1 0.1"/>
    </body>
  </worldbody>
  <actuator>
    <motor name="torque0" joint="joint0"  ctrlrange="-10 10" ctrllimited="true" />
  </actuator>
</mujoco>
